Workbook

Sheet 15-Sep
B2: FOURTEEN GROUP OF COMPANIES · AWAMI MARKET, KARKHANO, PESHAWAR | G2: Closing date | H2: 46280
B3: Closing — Rashid's Software, CRM & Salary | G3: Entries | H3: 7 JVs · 14 lines
B5: Period | D5: From – to | E5: Software & CRM | F5: Salary | G5: Total paid | H5: Owed to FMH + KBH
B6: 43 days | D6: 24-Apr-26 → 05-Jun-26 | E6: =H27 | F6: =H28 | G6: =H22 | H6: =-(H10+H11)
B8: Balances brought forward and closing | H8: Amounts in brackets are what Awami owes
B9: Code | C9: Account | E9: Opening b/f | F9: Debit | G9: Credit | H9: Closing
B10: 22100 | C10: FMH - Fourteen Manzil Heights | E10: 0 | F10: =SUMIFS(Entries!$G$2:$G$155,Entries!$C$2:$C$155,"Due to / from Group Companies:FMH - Fourteen Manzil Heights",Entries!$J$2:$J$155,"15-Sep") | G10: =SUMIFS(Entries!$H$2:$H$155,Entries!$C$2:$C$155,"Due to / from Group Companies:FMH - Fourteen Manzil Heights",Entries!$J$2:$J$155,"15-Sep") | H10: =E10+F10-G10
B11: 22200 | C11: KBH - Khushal Bagh Heights | E11: 0 | F11: =SUMIFS(Entries!$G$2:$G$155,Entries!$C$2:$C$155,"Due to / from Group Companies:KBH - Khushal Bagh Heights",Entries!$J$2:$J$155,"15-Sep") | G11: =SUMIFS(Entries!$H$2:$H$155,Entries!$C$2:$C$155,"Due to / from Group Companies:KBH - Khushal Bagh Heights",Entries!$J$2:$J$155,"15-Sep") | H11: =E11+F11-G11
B13: Payments made on Awami's behalf | H13: Paid by FMH or KBH · no Awami cash or bank used
B14: Date | C14: Voucher | D14: Description | E14: Head (COA) | F14: Payee | G14: Paid through | H14: Amount
B15: 46136 | C15: JV-0025 | D15: Paid for laptop c/o Rashid | E15: 15300 · Computer & IT Equipment | F15: Rashid | G15: FMH | H15: 95000
B16: 46147 | C16: JV-0029 | D16: Paid to Rashid as salary April 2026 | E16: 70100 · Salaries & Wages | F16: Rashid | G16: FMH | H16: 50000
B17: 46164 | C17: JV-0052 | D17: Paid to Rashid Mansoor for CRM software - KBH ref CPV-8199 | E17: 16100 · Software & Licences | F17: Rashid | G17: KBH | H17: 8000
B18: 46165 | C18: JV-0053 | D18: Paid to Rashid Mansoor for QuickBooks - KBH ref CPV-8219 | E18: 16100 · Software & Licences | F18: Rashid | G18: KBH | H18: 100000
B19: 46167 | C19: JV-0054 | D19: Paid to Rashid Mansoor for QuickBooks - KBH ref CPV-8222 | E19: 16100 · Software & Licences | F19: Rashid | G19: KBH | H19: 200000
B20: 46175 | C20: JV-0032 | D20: Paid to Rashid saib for QuickBooks software | E20: 16100 · Software & Licences | F20: Rashid | G20: FMH | H20: 80000
B21: 46178 | C21: JV-0030 | D21: Paid to Rashid for QuickBooks | E21: 16100 · Software & Licences | F21: Rashid | G21: FMH | H21: 100000
B22: ="FMH "&TEXT(SUMIFS(H15:H21,G15:G21,"FMH"),"#,##0")&" · KBH "&TEXT(SUMIFS(H15:H21,G15:G21,"KBH"),"#,##0") | G22: Total paid | H22: =SUM(H15:H21)
B24: Summary by head | H24: Expenses and assets charged
B25: Code | C25: Head | H25: Amount
B26: 15300 | C26: Computer & IT Equipment | H26: =SUMIFS(Entries!$G$2:$G$155,Entries!$C$2:$C$155,"Fixed Assets:Computer & IT Equipment",Entries!$J$2:$J$155,"15-Sep")-SUMIFS(Entries!$H$2:$H$155,Entries!$C$2:$C$155,"Fixed Assets:Computer & IT Equipment",Entries!$J$2:$J$155,"15-Sep")
B27: 16100 | C27: Software & Licences | H27: =SUMIFS(Entries!$G$2:$G$155,Entries!$C$2:$C$155,"Other Assets:Software & Licences",Entries!$J$2:$J$155,"15-Sep")-SUMIFS(Entries!$H$2:$H$155,Entries!$C$2:$C$155,"Other Assets:Software & Licences",Entries!$J$2:$J$155,"15-Sep")
B28: 70100 | C28: Salaries & Wages | H28: =SUMIFS(Entries!$G$2:$G$155,Entries!$C$2:$C$155,"Administrative Expenses:Salaries & Wages",Entries!$J$2:$J$155,"15-Sep")-SUMIFS(Entries!$H$2:$H$155,Entries!$C$2:$C$155,"Administrative Expenses:Salaries & Wages",Entries!$J$2:$J$155,"15-Sep")
G29: Total | H29: =SUM(H26:H28)
B31: Checks
C32: 1 | D32: Payments total ties to balances owed | G32: Must pass | H32: =IF(K32=0,"✓ OK","✗ "&K32&" issue") | K32: =IF(ROUND(H22-H6,0)=0,0,1)
C33: 2 | D33: Payments + head summary tie | G33: Must pass | H33: =IF(K33=0,"✓ OK","✗ "&K33&" issue") | K33: =IF(ROUND(H22-H29,0)=0,0,1)
B35: Remarks
B36: These are Rashid's own software (QuickBooks/CRM) and salary payments, funded by FMH/KBH on Awami's behalf — carved out of the 16-Sep closing at his request, purely for how it's presented here. QuickBooks itself needs no change: these entries are already posted there correctly under the FMH/KBH journal entries.
B40: Prepared by (Accountant) | D40: Checked by | G40: Approved by (Director)
B42: Source: Awami_All_Entries.xlsx (Entries sheet) · Split out from 16-Sep at Rashid's instruction · Dates are voucher dates

Sheet 16-Sep
B2: FOURTEEN GROUP OF COMPANIES · AWAMI MARKET, KARKHANO, PESHAWAR | G2: Closing date | H2: 46281
B3: Consolidated Closing — All Entries to Date | G3: Entries | H3: 57 JVs · 140 lines
B5: Period | D5: From – to | E5: Token money (net) | F5: Expenses paid | G5: With Yousaf Shah | H5: Owed to FMH + KBH
B6: 225 days | D6: 06-Feb-26 → 18-Sep-26 | E6: =H37 | F6: =H75 | G6: =H14 | H6: =-(H15+H16)
B8: Balances brought forward and closing | H8: Amounts in brackets are what Awami owes
B9: Code | C9: Account | E9: Opening b/f | F9: Debit | G9: Credit | H9: Closing
B10: 10100 | C10: Cash in Hand | E10: 0 | F10: =SUMIFS(Entries!$G$2:$G$155,Entries!$C$2:$C$155,"Cash & Bank:Cash in Hand") | G10: =SUMIFS(Entries!$H$2:$H$155,Entries!$C$2:$C$155,"Cash & Bank:Cash in Hand") | H10: =E10+F10-G10
B11: 10200 | C11: Petty Cash | E11: 0 | F11: =SUMIFS(Entries!$G$2:$G$155,Entries!$C$2:$C$155,"Cash & Bank:Petty Cash") | G11: =SUMIFS(Entries!$H$2:$H$155,Entries!$C$2:$C$155,"Cash & Bank:Petty Cash") | H11: =E11+F11-G11
B12: 10300 | C12: Bank Al-Habib - Awami Market | E12: 0 | F12: =SUMIFS(Entries!$G$2:$G$155,Entries!$C$2:$C$155,"Cash & Bank:Bank Al-Habib - Awami Market") | G12: =SUMIFS(Entries!$H$2:$H$155,Entries!$C$2:$C$155,"Cash & Bank:Bank Al-Habib - Awami Market") | H12: =E12+F12-G12
B13: Not cash — money held or owed on Awami's behalf
B14: 12610 | C14: Due from Syed Yousaf Shah (receivable, not cash) | E14: 0 | F14: =SUMIFS(Entries!$G$2:$G$158,Entries!$C$2:$C$158,"Current Assets:Due from Directors:Syed Yousaf Shah") | G14: =SUMIFS(Entries!$H$2:$H$158,Entries!$C$2:$C$158,"Current Assets:Due from Directors:Syed Yousaf Shah") | H14: =E14+F14-G14
B15: 22100 | C15: FMH - Fourteen Manzil Heights | E15: 0 | F15: =SUMIFS(Entries!$G$2:$G$155,Entries!$C$2:$C$155,"Due to / from Group Companies:FMH - Fourteen Manzil Heights",Entries!$J$2:$J$155,"16-Sep") | G15: =SUMIFS(Entries!$H$2:$H$155,Entries!$C$2:$C$155,"Due to / from Group Companies:FMH - Fourteen Manzil Heights",Entries!$J$2:$J$155,"16-Sep") | H15: =E15+F15-G15
B16: 22200 | C16: KBH - Khushal Bagh Heights | E16: 0 | F16: =SUMIFS(Entries!$G$2:$G$155,Entries!$C$2:$C$155,"Due to / from Group Companies:KBH - Khushal Bagh Heights",Entries!$J$2:$J$155,"16-Sep") | G16: =SUMIFS(Entries!$H$2:$H$155,Entries!$C$2:$C$155,"Due to / from Group Companies:KBH - Khushal Bagh Heights",Entries!$J$2:$J$155,"16-Sep") | H16: =E16+F16-G16
B17: 21100 | C17: Token Money - Units (customer advances) | E17: 0 | F17: =SUMIFS(Entries!$G$2:$G$155,Entries!$C$2:$C$155,"Customer Advances:Token Money - Units") | G17: =SUMIFS(Entries!$H$2:$H$155,Entries!$C$2:$C$155,"Customer Advances:Token Money - Units") | H17: =E17+F17-G17
B19: Token money received | H19: Credit 21100 · money came in through FMH office or director
B20: Date | C20: Voucher | D20: Token · buyer : units | F20: Class | G20: Received through | H20: Amount
B21: 46189 | C21: JV-0016 | D21: Token 101 · Abdullah: LG-03 | F21: LG | G21: FMH | H21: 250000
B22: 46213 | C22: JV-0001 | D22: Token 102 · Suhail: GF-129 | F22: GF | G22: FMH · Cash | H22: 10000
B23: 46232 | C23: JV-0002 | D23: Token 103 · Hassan Jan: GF-129 | F23: GF | G23: FMH · Online to 14 Development | H23: 40000
B24: 46253 | C24: JV-0003 | D24: Token 105 · Raza Ullah: GF-112 | F24: GF | G24: FMH · Cash | H24: 10000
B25: 46253 | C25: JV-0004 | D25: Token 106 · Raza Ullah: GF-176 | F25: GF | G25: FMH · Cash | H25: 10000
B26: 46262 | C26: JV-0005 | D26: Token 107 · Samin Khan Bangash: LG-132, LG-133 | F26: LG | G26: FMH · Cash | H26: 10000
B27: 46266 | C27: JV-0006 | D27: Token 108 · Hassan Jan: GF-129 | F27: GF | G27: FMH · Online to 14 Development | H27: 100000
B28: 46269 | C28: JV-0007 | D28: Token 109 · Haji Ibrar: LG-05, LG-06 · Waqar Ahmad - Units: LG-47 to LG-50, LG-91 to LG-93 | F28: LG | G28: FMH · Cash | H28: 500000
B29: 46269 | C29: JV-0008 | D29: Token 110 · Hussain: LG-54, LG-97 | F29: LG | G29: FMH · Cash | H29: 200000
B30: 46270 | C30: JV-0009 | D30: Token 111 · Haji Ibrar: LG-01 to LG-09 | F30: LG | G30: FMH · Cash | H30: 600000
B31: 46270 | C31: JV-0010 | D31: Token 112 · Malak Ibrar: GF-13 | F31: GF | G31: FMH · Cash | H31: 500000
B32: 46276 | C32: JV-0011 | D32: Token 113 · Meena Gul: LG-51 to LG-53, LG-94 to LG-96, GF-90 | F32: GF/LG | G32: Syed Yousaf Shah · Cash | H32: 800000
... B36: 46283 | C36: JV-0017 | D36: Refund: Token 101 · Abdullah: LG-03 | F36: LG | G36: FMH | H36: -250000
B37: 15 tokens received, 1 refunded | G37: Net token money | H37: =SUM(H21:H36)
B39: Payments made on Awami's behalf | H39: Paid by FMH, KBH or director · no Awami cash or bank used
B40: Date | C40: Voucher | D40: Description | E40: Head (COA) | F40: Payee | G40: Paid through | H40: Amount
B41: 46059 | C41: JV-0018 | D41: Ch# 10318764 deposited to Yousaf saib UBL | E41: 51100 · Land Purchase Cost | F41: Syed Yousaf Shah | G41: FMH | H41: 10000000
B42: 46111 | C42: JV-0019 | D42: Ch# 10323992 issued to Yousaf saib as loan return | E42: 51100 · Land Purchase Cost | F42: Syed Yousaf Shah | G42: FMH | H42: 4000000
B43: 46111 | C43: JV-0020 | D43: Ch# 10323992 issued to Yousaf saib as loan return - second entry | E43: 51100 · Land Purchase Cost | F43: Syed Yousaf Shah | G43: FMH | H43: 4000000
B44: 46129 | C44: JV-0021 | D44: Paid to Kashif as stamp navi | E44: 70500 · Printing & Stationery | F44: Kashif | G44: FMH | H44: 15000
B45: 46132 | C45: JV-0022 | D45: Paid to Waqar easypaisa for project MAP | E45: 60300 · Marketing Printing & Material | F45: Waqar Easypaisa | G45: FMH | H45: 10000
B46: 46133 | C46: JV-0023 | D46: Paid to Shah Khalid online by Naeem saib | E46: 53100 · Architecture, Design & Drawings | F46: Shah Khalid | G46: FMH | H46: 500000
B47: 46135 | C47: JV-0024 | D47: Ch# 10324016 issued to Alam c/o Dr Irshad | E47: 53200 · Soil Testing & Survey | F47: Alam | G47: FMH | H47: 100000
B48: 46139 | C48: JV-0026 | D48: Paid for Kharkhano map laptop | E48: 15300 · Computer & IT Equipment | G48: FMH | H48: 35000
...

Sheet 17-Sep
B2: FOURTEEN GROUP · AWAMI MARKET, KARKHANO | G2: Date | H2: 46282
B3: Daily Closing | G3: Day | H3: =TEXT(H2,"dddd")
B6: Opening Balance | C6: Money In | D6: Money Out | E6: Closing Balance | F6: =IF(SUM(K54:K57)=0,"✓ Balanced","⚠ Needs Review")
B7: =D14 | C7: =E14 | D7: =F14 | E7: =H14
B9: Cash & Bank
C10: Account | D10: Opening Balance | E10: Money In | F10: Money Out | G10: Transfer/Adjust | H10: Closing Balance
C11: Cash in Hand | D11: ='16-Sep'!H10 | E11: =SUMIFS($H$19:$H$26,$G$19:$G$26,"Cash") | F11: =SUMIFS($H$32:$H$41,$G$32:$G$41,"Cash") | G11: =-$D$15+$F$15-$H$15 | H11: =D11+E11-F11+G11
C12: Petty Cash | D12: ='16-Sep'!H11 | E12: =SUMIFS($H$19:$H$26,$G$19:$G$26,"Petty") | F12: =SUMIFS($H$32:$H$41,$G$32:$G$41,"Petty") | G12: =$H$15 | H12: =D12+E12-F12+G12
C13: Bank Al-Habib | D13: ='16-Sep'!H12 | E13: =SUMIFS($H$19:$H$26,$G$19:$G$26,"Bank") | F13: =SUMIFS($H$32:$H$41,$G$32:$G$41,"Bank") | G13: =$D$15-$F$15 | H13: =D13+E13-F13+G13
C14: Total | D14: =SUM(D11:D13) | E14: =SUM(E11:E13) | F14: =SUM(F11:F13) | G14: =SUM(G11:G13) | H14: =SUM(H11:H13)
C15: Cash → Bank Deposit | E15: Bank → Cash Withdrawal | G15: Cash → Petty Cash
B17: Money Received
B18: Voucher | C18: Description | D18: Head | F18: Floor | G18: Cash/Bank | H18: Amount Received
K19: =IF(D19="","",IFERROR(VALUE(LEFT(D19,5)),""))
K20: =IF(D20="","",IFERROR(VALUE(LEFT(D20,5)),""))
K21: =IF(D21="","",IFERROR(VALUE(LEFT(D21,5)),""))
K22: =IF(D22="","",IFERROR(VALUE(LEFT(D22,5)),""))
K23: =IF(D23="","",IFERROR(VALUE(LEFT(D23,5)),""))
K24: =IF(D24="","",IFERROR(VALUE(LEFT(D24,5)),""))
K25: =IF(D25="","",IFERROR(VALUE(LEFT(D25,5)),""))
K26: =IF(D26="","",IFERROR(VALUE(LEFT(D26,5)),""))
C27: =COUNT($H$19:$H$26)&" entries" | G27: Total Received | H27: =SUM($H$19:$H$26)
B30: Money Paid
B31: Voucher | C31: Description | D31: Head | F31: Floor | G31: Cash/Bank | H31: Amount Paid
K32: =IF(D32="","",IFERROR(VALUE(LEFT(D32,5)),""))
K33: =IF(D33="","",IFERROR(VALUE(LEFT(D33,5)),""))
K34: =IF(D34="","",IFERROR(VALUE(LEFT(D34,5)),""))
K35: =IF(D35="","",IFERROR(VALUE(LEFT(D35,5)),""))
K36: =IF(D36="","",IFERROR(VALUE(LEFT(D36,5)),""))
K37: =IF(D37="","",IFERROR(VALUE(LEFT(D37,5)),""))
K38: =IF(D38="","",IFERROR(VALUE(LEFT(D38,5)),""))
K39: =IF(D39="","",IFERROR(VALUE(LEFT(D39,5)),""))
K40: =IF(D40="","",IFERROR(VALUE(LEFT(D40,5)),""))
K41: =IF(D41="","",IFERROR(VALUE(LEFT(D41,5)),""))
C42: =COUNT($H$32:$H$41)&" entries" | G42: Total Paid | H42: =SUM($H$32:$H$41)
B44: Other Balances (Not Awami's Own Cash)
B45: Owed to FMH (payable) | G45: ='16-Sep'!H15*-1
B46: Owed to KBH (payable) | G46: ='16-Sep'!H16*-1
B47: Due from Syed Yousaf Shah — given by Awami, to be recovered | G47: ='16-Sep'!H14
B48: Due from Naeem Hussain — given by Awami, to be recovered | G48: 0
...

Sheet Entries
A1: Voucher | B1: Date | C1: Account | D1: COA code | E1: Name | F1: Class | G1: Debit | H1: Credit | I1: Memo | J1: Closing
A2: JV-0001 | B2: 46213 | C2: Due to / from Group Companies:FMH - Fourteen Manzil Heights | D2: 22100 | E2: FMH | F2: Project-wide | G2: 10000 | I2: Token 102 received by FMH office - Cash | J2: 16-Sep
A3: JV-0001 | B3: 46213 | C3: Customer Advances:Token Money - Units | D3: 21100 | E3: Suhail:GF-129 | F3: GF | H3: 10000 | I3: Token 102 - unit GF-129 | J3: 16-Sep
A4: JV-0002 | B4: 46232 | C4: Due to / from Group Companies:FMH - Fourteen Manzil Heights | D4: 22100 | E4: FMH | F4: Project-wide | G4: 40000 | I4: Token 103 received by FMH office - Online to 14 Development | J4: 16-Sep
A5: JV-0002 | B5: 46232 | C5: Customer Advances:Token Money - Units | D5: 21100 | E5: Hassan Jan:GF-129 | F5: GF | H5: 40000 | I5: Token 103 - unit GF-129 | J5: 16-Sep
A6: JV-0003 | B6: 46253 | C6: Due to / from Group Companies:FMH - Fourteen Manzil Heights | D6: 22100 | E6: FMH | F6: Project-wide | G6: 10000 | I6: Token 105 received by FMH office - Cash | J6: 16-Sep
A7: JV-0003 | B7: 46253 | C7: Customer Advances:Token Money - Units | D7: 21100 | E7: Raza Ullah:GF-112 | F7: GF | H7: 10000 | I7: Token 105 - unit GF-112 | J7: 16-Sep
A8: JV-0004 | B8: 46253 | C8: Due to / from Group Companies:FMH - Fourteen Manzil Heights | D8: 22100 | E8: FMH | F8: Project-wide | G8: 10000 | I8: Token 106 received by FMH office - Cash | J8: 16-Sep
A9: JV-0004 | B9: 46253 | C9: Customer Advances:Token Money - Units | D9: 21100 | E9: Raza Ullah:GF-176 | F9: GF | H9: 10000 | I9: Token 106 - unit GF-176 | J9: 16-Sep
A10: JV-0005 | B10: 46262 | C10: Due to / from Group Companies:FMH - Fourteen Manzil Heights | D10: 22100 | E10: FMH | F10: Project-wide | G10: 10000 | I10: Token 107 received by FMH office - Cash | J10: 16-Sep
A11: JV-0005 | B11: 46262 | C11: Customer Advances:Token Money - Units | D11: 21100 | E11: Samin Khan Bangash:LG-132 | F11: LG | H11: 5000 | I11: Token 107 - unit LG-132 | J11: 16-Sep
A12: JV-0005 | B12: 46262 | C12: Customer Advances:Token Money - Units | D12: 21100 | E12: Samin Khan Bangash:LG-133 | F12: LG | H12: 5000 | I12: Token 107 - unit LG-133 | J12: 16-Sep
A13: JV-0006 | B13: 46266 | C13: Due to / from Group Companies:FMH - Fourteen Manzil Heights | D13: 22100 | E13: FMH | F13: Project-wide | G13: 100000 | I13: Token 108 received by FMH office - Online to 14 Development | J13: 16-Sep
A14: JV-0006 | B14: 46266 | C14: Customer Advances:Token Money - Units | D14: 21100 | E14: Hassan Jan:GF-129 | F14: GF | H14: 100000 | I14: Token 108 - unit GF-129 | J14: 16-Sep
A15: JV-0007 | B15: 46269 | C15: Due to / from Group Companies:FMH - Fourteen Manzil Heights | D15: 22100 | E15: FMH | F15: Project-wide | G15: 500000 | I15: Token 109 received by FMH office - Cash | J15: 16-Sep
A16: JV-0007 | B16: 46269 | C16: Customer Advances:Token Money - Units | D16: 21100 | E16: Haji Ibrar:LG-05 | F16: LG | H16: 55555.56 | I16: Token 109 - unit LG-05 | J16: 16-Sep
A17: JV-0007 | B17: 46269 | C17: Customer Advances:Token Money - Units | D17: 21100 | E17: Haji Ibrar:LG-06 | F17: LG | H17: 55555.56 | I17: Token 109 - unit LG-06 | J17: 16-Sep
A18: JV-0007 | B18: 46269 | C18: Customer Advances:Token Money - Units | D18: 21100 | E18: Waqar Ahmad - Units:LG-47 | F18: LG | H18: 55555.56 | I18: Token 109 - unit LG-47 | J18: 16-Sep
A19: JV-0007 | B19: 46269 | C19: Customer Advances:Token Money - Units | D19: 21100 | E19: Waqar Ahmad - Units:LG-48 | F19: LG | H19: 55555.56 | I19: Token 109 - unit LG-48 | J19: 16-Sep
A20: JV-0007 | B20: 46269 | C20: Customer Advances:Token Money - Units | D20: 21100 | E20: Waqar Ahmad - Units:LG-49 | F20: LG | H20: 55555.56 | I20: Token 109 - unit LG-49 | J20: 16-Sep
A21: JV-0007 | B21: 46269 | C21: Customer Advances:Token Money - Units | D21: 21100 | E21: Waqar Ahmad - Units:LG-50 | F21: LG | H21: 55555.56 | I21: Token 109 - unit LG-50 | J21: 16-Sep
A22: JV-0007 | B22: 46269 | C22: Customer Advances:Token Money - Units | D22: 21100 | E22: Waqar Ahmad - Units:LG-91 | F22: LG | H22: 55555.56 | I22: Token 109 - unit LG-91 | J22: 16-Sep
A23: JV-0007 | B23: 46269 | C23: Customer Advances:Token Money - Units | D23: 21100 | E23: Waqar Ahmad - Units:LG-92 | F23: LG | H23: 55555.56 | I23: Token 109 - unit LG-92 | J23: 16-Sep
A24: JV-0007 | B24: 46269 | C24: Customer Advances:Token Money - Units | D24: 21100 | E24: Waqar Ahmad - Units:LG-93 | F24: LG | H24: 55555.52 | I24: Token 109 - unit LG-93 | J24: 16-Sep
A25: JV-0008 | B25: 46269 | C25: Due to / from Group Companies:FMH - Fourteen Manzil Heights | D25: 22100 | E25: FMH | F25: Project-wide | G25: 200000 | I25: Token 110 received by FMH office - Cash | J25: 16-Sep
A26: JV-0008 | B26: 46269 | C26: Customer Advances:Token Money - Units | D26: 21100 | E26: Hussain:LG-54 | F26: LG | H26: 100000 | I26: Token 110 - unit LG-54 | J26: 16-Sep
A27: JV-0008 | B27: 46269 | C27: Customer Advances:Token Money - Units | D27: 21100 | E27: Hussain:LG-97 | F27: LG | H27: 100000 | I27: Token 110 - unit LG-97 | J27: 16-Sep
A28: JV-0009 | B28: 46270 | C28: Due to / from Group Companies:FMH - Fourteen Manzil Heights | D28: 22100 | E28: FMH | F28: Project-wide | G28: 600000 | I28: Token 111 received by FMH office - Cash | J28: 16-Sep
A29: JV-0009 | B29: 46270 | C29: Customer Advances:Token Money - Units | D29: 21100 | E29: Haji Ibrar:LG-01 | F29: LG | H29: 66666.67 | I29: Token 111 - unit LG-01 | J29: 16-Sep
A30: JV-0009 | B30: 46270 | C30: Customer Advances:Token Money - Units | D30: 21100 | E30: Haji Ibrar:LG-02 | F30: LG | H30: 66666.67 | I30: Token 111 - unit LG-02 | J30: 16-Sep
A31: JV-0009 | B31: 46270 | C31: Customer Advances:Token Money - Units | D31: 21100 | E31: Haji Ibrar:LG-03 | F31: LG | H31: 66666.67 | I31: Token 111 - unit LG-03 | J31: 16-Sep
A32: JV-0009 | B32: 46270 | C32: Customer Advances:Token Money - Units | D32: 21100 | E32: Haji Ibrar:LG-04 | F32: LG | H32: 66666.67 | I32: Token 111 - unit LG-04 | J32: 16-Sep
A33: JV-0009 | B33: 46270 | C33: Customer Advances:Token Money - Units | D33: 21100 | E33: Haji Ibrar:LG-05 | F33: LG | H33: 66666.67 | I33: Token 111 - unit LG-05 | J33: 16-Sep
A34: JV-0009 | B34: 46270 | C34: Customer Advances:Token Money - Units | D34: 21100 | E34: Haji Ibrar:LG-06 | F34: LG | H34: 66666.67 | I34: Token 111 - unit LG-06 | J34: 16-Sep
A35: JV-0009 | B35: 46270 | C35: Customer Advances:Token Money - Units | D35: 21100 | E35: Haji Ibrar:LG-07 | F35: LG | H35: 66666.67 | I35: Token 111 - unit LG-07 | J35: 16-Sep
A36: JV-0009 | B36: 46270 | C36: Customer Advances:Token Money - Units | D36: 21100 | E36: Haji Ibrar:LG-08 | F36: LG | H36: 66666.67 | I36: Token 111 - unit LG-08 | J36: 16-Sep
A37: JV-0009 | B37: 46270 | C37: Customer Advances:Token Money - Units | D37: 21100 | E37: Haji Ibrar:LG-09 | F37: LG | H37: 66666.64 | I37: Token 111 - unit LG-09 | J37: 16-Sep
A38: JV-0010 | B38: 46270 | C38: Due to / from Group Companies:FMH - Fourteen Manzil Heights | D38: 22100 | E38: FMH | F38: Project-wide | G38: 500000 | I38: Token 112 received by FMH office - Cash | J38: 16-Sep
A39: JV-0010 | B39: 46270 | C39: Customer Advances:Token Money - Units | D39: 21100 | E39: Malak Ibrar:GF-13 | F39: GF | H39: 500000 | I39: Token 112 - unit GF-13 | J39: 16-Sep
A40: JV-0011 | B40: 46276 | C40: Current Assets:Due from Directors:Syed Yousaf Shah | D40: 12610 | E40: Syed Yousaf Shah | F40: Project-wide | G40: 800000 | I40: Token 113 received by Syed Yousaf Shah - Cash | J40: 16-Sep
...

Sheet Heads
A1: Code | B1: Head name | C1: QB type | D1: Parent | E1: Pick label | F1: Received | G1: Paid | H1: Used #
A2: 12100 | B2: Supplier & Contractor Advances | C2: Other Current Asset | D2: Current Assets | E2: =IF(A2="","",A2&" · "&B2) | F2: =IF(A2="","",SUMIFS('17-Sep'!$H$19:$H$26,'17-Sep'!$K$19:$K$26,A2)) | G2: =IF(A2="","",SUMIFS('17-Sep'!$H$32:$H$41,'17-Sep'!$K$32:$K$41,A2))
A3: 12200 | B3: Staff Advances | C3: Other Current Asset | D3: Current Assets | E3: =IF(A3="","",A3&" · "&B3) | F3: =IF(A3="","",SUMIFS('17-Sep'!$H$19:$H$26,'17-Sep'!$K$19:$K$26,A3)) | G3: =IF(A3="","",SUMIFS('17-Sep'!$H$32:$H$41,'17-Sep'!$K$32:$K$41,A3))
A4: 12300 | B4: PDC Receivable | C4: Other Current Asset | D4: Current Assets | E4: =IF(A4="","",A4&" · "&B4) | F4: =IF(A4="","",SUMIFS('17-Sep'!$H$19:$H$26,'17-Sep'!$K$19:$K$26,A4)) | G4: =IF(A4="","",SUMIFS('17-Sep'!$H$32:$H$41,'17-Sep'!$K$32:$K$41,A4))
A5: 12400 | B5: Prepaid Expenses | C5: Other Current Asset | D5: Current Assets | E5: =IF(A5="","",A5&" · "&B5) | F5: =IF(A5="","",SUMIFS('17-Sep'!$H$19:$H$26,'17-Sep'!$K$19:$K$26,A5)) | G5: =IF(A5="","",SUMIFS('17-Sep'!$H$32:$H$41,'17-Sep'!$K$32:$K$41,A5))
A6: 12500 | B6: Security Deposits | C6: Other Current Asset | D6: Current Assets | E6: =IF(A6="","",A6&" · "&B6) | F6: =IF(A6="","",SUMIFS('17-Sep'!$H$19:$H$26,'17-Sep'!$K$19:$K$26,A6)) | G6: =IF(A6="","",SUMIFS('17-Sep'!$H$32:$H$41,'17-Sep'!$K$32:$K$41,A6))
A7: 12610 | B7: Syed Yousaf Shah | C7: Other Current Asset | D7: Due from Directors | E7: =IF(A7="","",A7&" · "&B7) | F7: =IF(A7="","",SUMIFS('17-Sep'!$H$19:$H$26,'17-Sep'!$K$19:$K$26,A7)) | G7: =IF(A7="","",SUMIFS('17-Sep'!$H$32:$H$41,'17-Sep'!$K$32:$K$41,A7))
A8: 12620 | B8: Naeem Hussain | C8: Other Current Asset | D8: Due from Directors | E8: =IF(A8="","",A8&" · "&B8) | F8: =IF(A8="","",SUMIFS('17-Sep'!$H$19:$H$26,'17-Sep'!$K$19:$K$26,A8)) | G8: =IF(A8="","",SUMIFS('17-Sep'!$H$32:$H$41,'17-Sep'!$K$32:$K$41,A8))
A9: 13100 | B9: Unsold Units - Shops | C9: Other Current Asset | D9: Project Inventory | E9: =IF(A9="","",A9&" · "&B9) | F9: =IF(A9="","",SUMIFS('17-Sep'!$H$19:$H$26,'17-Sep'!$K$19:$K$26,A9)) | G9: =IF(A9="","",SUMIFS('17-Sep'!$H$32:$H$41,'17-Sep'!$K$32:$K$41,A9))
A10: 15100 | B10: Furniture & Fixtures | C10: Fixed Asset | D10: Fixed Assets | E10: =IF(A10="","",A10&" · "&B10) | F10: =IF(A10="","",SUMIFS('17-Sep'!$H$19:$H$26,'17-Sep'!$K$19:$K$26,A10)) | G10: =IF(A10="","",SUMIFS('17-Sep'!$H$32:$H$41,'17-Sep'!$K$32:$K$41,A10))
A11: 15200 | B11: Office Equipment | C11: Fixed Asset | D11: Fixed Assets | E11: =IF(A11="","",A11&" · "&B11) | F11: =IF(A11="","",SUMIFS('17-Sep'!$H$19:$H$26,'17-Sep'!$K$19:$K$26,A11)) | G11: =IF(A11="","",SUMIFS('17-Sep'!$H$32:$H$41,'17-Sep'!$K$32:$K$41,A11))
A12: 15300 | B12: Computer & IT Equipment | C12: Fixed Asset | D12: Fixed Assets | E12: =IF(A12="","",A12&" · "&B12) | F12: =IF(A12="","",SUMIFS('17-Sep'!$H$19:$H$26,'17-Sep'!$K$19:$K$26,A12)) | G12: =IF(A12="","",SUMIFS('17-Sep'!$H$32:$H$41,'17-Sep'!$K$32:$K$41,A12))
A13: 15400 | B13: Vehicles | C13: Fixed Asset | D13: Fixed Assets | E13: =IF(A13="","",A13&" · "&B13) | F13: =IF(A13="","",SUMIFS('17-Sep'!$H$19:$H$26,'17-Sep'!$K$19:$K$26,A13)) | G13: =IF(A13="","",SUMIFS('17-Sep'!$H$32:$H$41,'17-Sep'!$K$32:$K$41,A13))
... A78: 85200 | B78: Markup & Interest | C78: Expense | D78: Financial Charges | E78: =IF(A78="","",A78&" · "&B78) | F78: =IF(A78="","",SUMIFS('17-Sep'!$H$19:$H$26,'17-Sep'!$K$19:$K$26,A78)) | G78: =IF(A78="","",SUMIFS('17-Sep'!$H$32:$H$41,'17-Sep'!$K$32:$K$41,A78))
E79: =IF(A79="","",A79&" · "&B79) | F79: =IF(A79="","",SUMIFS('17-Sep'!$H$19:$H$26,'17-Sep'!$K$19:$K$26,A79)) | G79: =IF(A79="","",SUMIFS('17-Sep'!$H$32:$H$41,'17-Sep'!$K$32:$K$41,A79))
E80: =IF(A80="","",A80&" · "&B80) | F80: =IF(A80="","",SUMIFS('17-Sep'!$H$19:$H$26,'17-Sep'!$K$19:$K$26,A80)) | G80: =IF(A80="","",SUMIFS('17-Sep'!$H$32:$H$41,'17-Sep'!$K$32:$K$41,A80))
E81: =IF(A81="","",A81&" · "&B81) | F81: =IF(A81="","",SUMIFS('17-Sep'!$H$19:$H$26,'17-Sep'!$K$19:$K$26,A81)) | G81: =IF(A81="","",SUMIFS('17-Sep'!$H$32:$H$41,'17-Sep'!$K$32:$K$41,A81))
E82: =IF(A82="","",A82&" · "&B82) | F82: =IF(A82="","",SUMIFS('17-Sep'!$H$19:$H$26,'17-Sep'!$K$19:$K$26,A82)) | G82: =IF(A82="","",SUMIFS('17-Sep'!$H$32:$H$41,'17-Sep'!$K$32:$K$41,A82))
E83: =IF(A83="","",A83&" · "&B83) | F83: =IF(A83="","",SUMIFS('17-Sep'!$H$19:$H$26,'17-Sep'!$K$19:$K$26,A83)) | G83: =IF(A83="","",SUMIFS('17-Sep'!$H$32:$H$41,'17-Sep'!$K$32:$K$41,A83))
E84: =IF(A84="","",A84&" · "&B84) | F84: =IF(A84="","",SUMIFS('17-Sep'!$H$19:$H$26,'17-Sep'!$K$19:$K$26,A84)) | G84: =IF(A84="","",SUMIFS('17-Sep'!$H$32:$H$41,'17-Sep'!$K$32:$K$41,A84))
E85: =IF(A85="","",A85&" · "&B85) | F85: =IF(A85="","",SUMIFS('17-Sep'!$H$19:$H$26,'17-Sep'!$K$19:$K$26,A85)) | G85: =IF(A85="","",SUMIFS('17-Sep'!$H$32:$H$41,'17-Sep'!$K$32:$K$41,A85))
E86: =IF(A86="","",A86&" · "&B86) | F86: =IF(A86="","",SUMIFS('17-Sep'!$H$19:$H$26,'17-Sep'!$K$19:$K$26,A86)) | G86: =IF(A86="","",SUMIFS('17-Sep'!$H$32:$H$41,'17-Sep'!$K$32:$K$41,A86))
E87: =IF(A87="","",A87&" · "&B87) | F87: =IF(A87="","",SUMIFS('17-Sep'!$H$19:$H$26,'17-Sep'!$K$19:$K$26,A87)) | G87: =IF(A87="","",SUMIFS('17-Sep'!$H$32:$H$41,'17-Sep'!$K$32:$K$41,A87))
E88: =IF(A88="","",A88&" · "&B88) | F88: =IF(A88="","",SUMIFS('17-Sep'!$H$19:$H$26,'17-Sep'!$K$19:$K$26,A88)) | G88: =IF(A88="","",SUMIFS('17-Sep'!$H$32:$H$41,'17-Sep'!$K$32:$K$41,A88))
E89: =IF(A89="","",A89&" · "&B89) | F89: =IF(A89="","",SUMIFS('17-Sep'!$H$19:$H$26,'17-Sep'!$K$19:$K$26,A89)) | G89: =IF(A89="","",SUMIFS('17-Sep'!$H$32:$H$41,'17-Sep'!$K$32:$K$41,A89))
E90: =IF(A90="","",A90&" · "&B90) | F90: =IF(A90="","",SUMIFS('17-Sep'!$H$19:$H$26,'17-Sep'!$K$19:$K$26,A90)) | G90: =IF(A90="","",SUMIFS('17-Sep'!$H$32:$H$41,'17-Sep'!$K$32:$K$41,A90))
... E150: =IF(A150="","",A150&" · "&B150) | F150: =IF(A150="","",SUMIFS('17-Sep'!$H$19:$H$26,'17-Sep'!$K$19:$K$26,A150)) | G150: =IF(A150="","",SUMIFS('17-Sep'!$H$32:$H$41,'17-Sep'!$K$32:$K$41,A150))

Sheet Lists
A1: Class | B1: Via
A2: LG | B2: Cash
A3: GF | B3: Petty
A4: FF | B4: Bank
A5: SF
A6: TF
A7: 4F
A8: 5F
A9: CB
A10: Project-wide
